Workbook

Sheet Schedule
Z1: Week 1 | AI1: Week 2 | AR1: Week 3 | BA1: Week 4 | BJ1: Week 5 | BS1: Week 6 | CB1: Week 7 | CK1: Week 8 | CT1: Week 9 | DC1: Week 10 | DL1: Week 11 | DU1: Week 12 | ED1: Week 13 | EM1: Week 14 | EV1: Week 15 | FE1: Week 16 | FN1: Week 17 | FW1: Week 18 | GF1: Week 19 | GO1: Week 20
B2: Start Date
B3: No. of weeks
A4: {=_xlfn.SEQUENCE(C3,1,C2,7)} -> #VALUE!
B5: Market | C5: Asset | D5: =A4 -> #VALUE! | E5: =A5 -> 0 | F5: =A6 -> 0 | G5: =A7 -> 0 | H5: =A8 -> 0 | I5: =A9 -> 0 | J5: =A10 -> 0 | K5: =A11 -> 0 | L5: =A12 -> 0 | M5: =A13 -> 0 | N5: =A14 -> 0 | O5: =A15 -> 0 | P5: =A16 -> 0 | Q5: =A17 -> 0 | R5: =A18 -> 0 | S5: =A19 -> 0 | T5: =A20 -> 0 | U5: =A21 -> 0 | V5: =A22 -> 0 | W5: =A23 -> 0 | Z5: 8-sheet | AA5: 6-sheet | AB5: 4-sheet | AC5: 2-sheet | AD5: QA0 | AE5: Mega | AF5: DOT M | AG5: MP | AH5: FF | AI5: 8-sheet | AJ5: 6-sheet | AK5: 4-sheet | AL5: 2-sheet | AM5: QA0 | AN5: Mega | AO5: DOT M | AP5: MP | AQ5: FF | AR5: 8-sheet | AS5: 6-sheet | AT5: 4-sheet | AU5: 2-sheet | AV5: QA0 | AW5: Mega | AX5: DOT M | AY5: MP | AZ5: FF | BA5: 8-sheet | BB5: 6-sheet | BC5: 4-sheet | BD5: 2-sheet | BE5: QA0 | BF5: Mega | BG5: DOT M | BH5: MP | BI5: FF | BJ5: 8-sheet | BK5: 6-sheet | BL5: 4-sheet | BM5: 2-sheet | BN5: QA0 | BO5: Mega | BP5: DOT M | BQ5: MP | BR5: FF | BS5: 8-sheet | BT5: 6-sheet | BU5: 4-sheet | BV5: 2-sheet | BW5: QA0 | BX5: Mega | BY5: DOT M | BZ5: MP | CA5: FF | CB5: 8-sheet | CC5: 6-sheet | CD5: 4-sheet | CE5: 2-sheet | CF5: QA0 | CG5: Mega | CH5: DOT M | CI5: MP | CJ5: FF | CK5: 8-sheet | CL5: 6-sheet | CM5: 4-sheet | CN5: 2-sheet | CO5: QA0 | CP5: Mega | CQ5: DOT M | CR5: MP | CS5: FF | CT5: 8-sheet | CU5: 6-sheet | CV5: 4-sheet | CW5: 2-sheet | CX5: QA0 | CY5: Mega | CZ5: DOT M | DA5: MP | DB5: FF | DC5: 8-sheet | DD5: 6-sheet | DE5: 4-sheet | DF5: 2-sheet | DG5: QA0 | DH5: Mega | DI5: DOT M | DJ5: MP | DK5: FF | DL5: 8-sheet | DM5: 6-sheet | DN5: 4-sheet | DO5: 2-sheet | DP5: QA0 | DQ5: Mega | DR5: DOT M | DS5: MP | DT5: FF | DU5: 8-sheet | DV5: 6-sheet | DW5: 4-sheet | DX5: 2-sheet | DY5: QA0 | DZ5: Mega | EA5: DOT M | EB5: MP | EC5: FF | ED5: 8-sheet | EE5: 6-sheet | EF5: 4-sheet | EG5: 2-sheet | EH5: QA0 | EI5: Mega | EJ5: DOT M | EK5: MP | EL5: FF | EM5: 8-sheet | EN5: 6-sheet | EO5: 4-sheet | EP5: 2-sheet | EQ5: QA0 | ER5: Mega | ES5: DOT M | ET5: MP | EU5: FF | EV5: 8-sheet | EW5: 6-sheet | EX5: 4-sheet | EY5: 2-sheet | EZ5: QA0 | FA5: Mega | FB5: DOT M | FC5: MP | FD5: FF | FE5: 8-sheet | FF5: 6-sheet | FG5: 4-sheet | FH5: 2-sheet | FI5: QA0 | FJ5: Mega | FK5: DOT M | FL5: MP | FM5: FF | FN5: 8-sheet | FO5: 6-sheet | FP5: 4-sheet | FQ5: 2-sheet | FR5: QA0 | FS5: Mega | FT5: DOT M | FU5: MP | FV5: FF | FW5: 8-sheet | FX5: 6-sheet | FY5: 4-sheet | FZ5: 2-sheet | GA5: QA0 | GB5: Mega | GC5: DOT M | GD5: MP | GE5: FF | GF5: 8-sheet | GG5: 6-sheet | GH5: 4-sheet | GI5: 2-sheet | GJ5: QA0 | GK5: Mega | GL5: DOT M | GM5: MP | GN5: FF | GO5: 8-sheet | GP5: 6-sheet | GQ5: 4-sheet | GR5: 2-sheet | GS5: QA0 | GT5: Mega | GU5: DOT M | GV5: MP | GW5: FF
B6: Sydney | Y6: Sydney | Z6: =IF(AND($C6<>"",$D6<>""),(VLOOKUP($C6,'V-LOOKUP'!$C$4:$M$59,4,FALSE)),"0") -> 0 | AA6: =IF(AND($C6<>"",$D6<>""),(VLOOKUP($C6,'V-LOOKUP'!$C$4:$M$59,5,FALSE)),"0") -> 0 | AB6: =IF(AND($C6<>"",$D6<>""),(VLOOKUP($C6,'V-LOOKUP'!$C$4:$M$59,6,FALSE)),"0") -> 0 | AC6: =IF(AND($C6<>"",$D6<>""),(VLOOKUP($C6,'V-LOOKUP'!$C$4:$M$59,7,FALSE)),"0") -> 0 | AD6: =IF(AND($C6<>"",$D6<>""),(VLOOKUP($C6,'V-LOOKUP'!$C$4:$M$59,8,FALSE)),"0") -> 0 | AE6: =IF(AND($C6<>"",$D6<>""),(VLOOKUP($C6,'V-LOOKUP'!$C$4:$M$59,9,FALSE)),"0") -> 0 | AF6: =IF(AND($C6<>"",$D6<>""),(VLOOKUP($C6,'V-LOOKUP'!$C$4:$M$59,10,FALSE)),"0") -> 0 | AG6: =IF(AND($C6<>"",$D6<>""),(VLOOKUP($C6,'V-LOOKUP'!$C$4:$M$59,11,FALSE)),"0") -> 0 | AH6: =IF(AND($C6<>"",$D6<>""),(VLOOKUP($C6,'V-LOOKUP'!$C$4:$N$59,12,FALSE)),"0") -> 0 | AI6: =IF(AND($C6<>"",E6<>""),(VLOOKUP($C6,'V-LOOKUP'!$C$4:$M$59,4,FALSE)),"0") -> 0 | AJ6: =IF(AND($C6<>"",$E6<>""),(VLOOKUP($C6,'V-LOOKUP'!$C$4:$M$59,5,FALSE)),"0") -> 0 | AK6: =IF(AND($C6<>"",$E6<>""),(VLOOKUP($C6,'V-LOOKUP'!$C$4:$M$59,6,FALSE)),"0") -> 0 | AL6: =IF(AND($C6<>"",$E6<>""),(VLOOKUP($C6,'V-LOOKUP'!$C$4:$M$59,7,FALSE)),"0") -> 0 | AM6: =IF(AND($C6<>"",$E6<>""),(VLOOKUP($C6,'V-LOOKUP'!$C$4:$M$59,8,FALSE)),"0") -> 0 | AN6: =IF(AND($C6<>"",$E6<>""),(VLOOKUP($C6,'V-LOOKUP'!$C$4:$M$59,9,FALSE)),"0") -> 0 | AO6: =IF(AND($C6<>"",$E6<>""),(VLOOKUP($C6,'V-LOOKUP'!$C$4:$M$59,10,FALSE)),"0") -> 0 | AP6: =IF(AND($C6<>"",$E6<>""),(VLOOKUP($C6,'V-LOOKUP'!$C$4:$M$59,11,FALSE)),"0") -> 0 | AQ6: =IF(AND($C6<>"",$E6<>""),(VLOOKUP($C6,'V-LOOKUP'!$C$4:$N$59,12,FALSE)),"0") -> 0 | AR6: =IF(AND($C6<>"",$F6<>""),(VLOOKUP($C6,'V-LOOKUP'!$C$4:$M$59,4,FALSE)),"0") -> 0 | AS6: =IF(AND($C6<>"",$F6<>""),(VLOOKUP($C6,'V-LOOKUP'!$C$4:$M$59,5,FALSE)),"0") -> 0 | AT6: =IF(AND($C6<>"",$F6<>""),(VLOOKUP($C6,'V-LOOKUP'!$C$4:$M$59,6,FALSE)),"0") -> 0 | AU6: =IF(AND($C6<>"",$F6<>""),(VLOOKUP($C6,'V-LOOKUP'!$C$4:$M$59,7,FALSE)),"0") -> 0 | AV6: =IF(AND($C6<>"",$F6<>""),(VLOOKUP($C6,'V-LOOKUP'!$C$4:$M$59,8,FALSE)),"0") -> 0 | AW6: =IF(AND($C6<>"",$F6<>""),(VLOOKUP($C6,'V-LOOKUP'!$C$4:$M$59,9,FALSE)),"0") -> 0 | AX6: =IF(AND($C6<>"",$F6<>""),(VLOOKUP($C6,'V-LOOKUP'!$C$4:$M$59,10,FALSE)),"0") -> 0 | AY6: =IF(AND($C6<>"",$F6<>""),(VLOOKUP($C6,'V-LOOKUP'!$C$4:$M$59,11,FALSE)),"0") -> 0 | AZ6: =IF(AND($C6<>"",$F6<>""),(VLOOKUP($C6,'V-LOOKUP'!$C$4:$N$59,12,FALSE)),"0") -> 0 | BA6: =IF(AND($C6<>"",G6<>""),(VLOOKUP($C6,'V-LOOKUP'!$C$4:$M$59,4,FALSE)),"0") -> 0 | BB6: =IF(AND($C6<>"",$G6<>""),(VLOOKUP($C6,'V-LOOKUP'!$C$4:$M$59,5,FALSE)),"0") -> 0 | BC6: =IF(AND($C6<>"",$G6<>""),(VLOOKUP($C6,'V-LOOKUP'!$C$4:$M$59,6,FALSE)),"0") -> 0 | BD6: =IF(AND($C6<>"",$G6<>""),(VLOOKUP($C6,'V-LOOKUP'!$C$4:$M$59,7,FALSE)),"0") -> 0 | BE6: =IF(AND($C6<>"",$G6<>""),(VLOOKUP($C6,'V-LOOKUP'!$C$4:$M$59,8,FALSE)),"0") -> 0 | BF6: =IF(AND($C6<>"",$G6<>""),(VLOOKUP($C6,'V-LOOKUP'!$C$4:$M$59,9,FALSE)),"0") -> 0 | BG6: =IF(AND($C6<>"",$G6<>""),(VLOOKUP($C6,'V-LOOKUP'!$C$4:$M$59,10,FALSE)),"0") -> 0 | BH6: =IF(AND($C6<>"",$G6<>""),(VLOOKUP($C6,'V-LOOKUP'!$C$4:$M$59,11,FALSE)),"0") -> 0 | BI6: =IF(AND($C6<>"",$G6<>""),(VLOOKUP($C6,'V-LOOKUP'!$C$4:$N$59,12,FALSE)),"0") -> 0 | BJ6: =IF(AND($C6<>"",H6<>""),(VLOOKUP($C6,'V-LOOKUP'!$C$4:$M$59,4,FALSE)),"0") -> 0 | BK6: =IF(AND($C6<>"",$G6<>""),(VLOOKUP($C6,'V-LOOKUP'!$C$4:$M$59,5,FALSE)),"0") -> 0 | BL6: =IF(AND($C6<>"",$H6<>""),(VLOOKUP($C6,'V-LOOKUP'!$C$4:$M$59,6,FALSE)),"0") -> 0 | BM6: =IF(AND($C6<>"",$H6<>""),(VLOOKUP($C6,'V-LOOKUP'!$C$4:$M$59,7,FALSE)),"0") -> 0 | BN6: =IF(AND($C6<>"",$H6<>""),(VLOOKUP($C6,'V-LOOKUP'!$C$4:$M$59,8,FALSE)),"0") -> 0 | BO6: =IF(AND($C6<>"",$H6<>""),(VLOOKUP($C6,'V-LOOKUP'!$C$4:$M$59,9,FALSE)),"0") -> 0 | BP6: =IF(AND($C6<>"",$H6<>""),(VLOOKUP($C6,'V-LOOKUP'!$C$4:$M$59,10,FALSE)),"0") -> 0 | BQ6: =IF(AND($C6<>"",$H6<>""),(VLOOKUP($C6,'V-LOOKUP'!$C$4:$M$59,11,FALSE)),"0") -> 0 | BR6: =IF(AND($C6<>"",$H6<>""),(VLOOKUP($C6,'V-LOOKUP'!$C$4:$N$59,12,FALSE)),"0") -> 0 | BS6: =IF(AND($C6<>"",I6<>""),(VLOOKUP($C6,'V-LOOKUP'!$C$4:$M$59,4,FALSE)),"0") -> 0 | BT6: =IF(AND($C6<>"",$I6<>""),(VLOOKUP($C6,'V-LOOKUP'!$C$4:$M$59,5,FALSE)),"0") -> 0 | BU6: =IF(AND($C6<>"",$I6<>""),(VLOOKUP($C6,'V-LOOKUP'!$C$4:$M$59,6,FALSE)),"0") -> 0 | BV6: =IF(AND($C6<>"",$I6<>""),(VLOOKUP($C6,'V-LOOKUP'!$C$4:$M$59,7,FALSE)),"0") -> 0 | BW6: =IF(AND($C6<>"",$I6<>""),(VLOOKUP($C6,'V-LOOKUP'!$C$4:$M$59,8,FALSE)),"0") -> 0 | BX6: =IF(AND($C6<>"",$I6<>""),(VLOOKUP($C6,'V-LOOKUP'!$C$4:$M$59,9,FALSE)),"0") -> 0 | BY6: =IF(AND($C6<>"",$I6<>""),(VLOOKUP($C6,'V-LOOKUP'!$C$4:$M$59,10,FALSE)),"0") -> 0 | BZ6: =IF(AND($C6<>"",$I6<>""),(VLOOKUP($C6,'V-LOOKUP'!$C$4:$M$59,11,FALSE)),"0") -> 0 | CA6: =IF(AND($C6<>"",$I6<>""),(VLOOKUP($C6,'V-LOOKUP'!$C$4:$N$59,12,FALSE)),"0") -> 0 | CB6: =IF(AND($C6<>"",J6<>""),(VLOOKUP($C6,'V-LOOKUP'!$C$4:$M$59,4,FALSE)),"0") -> 0 | CC6: =IF(AND($C6<>"",$J6<>""),(VLOOKUP($C6,'V-LOOKUP'!$C$4:$M$59,5,FALSE)),"0") -> 0 | CD6: =IF(AND($C6<>"",$J6<>""),(VLOOKUP($C6,'V-LOOKUP'!$C$4:$M$59,6,FALSE)),"0") -> 0 | CE6: =IF(AND($C6<>"",$J6<>""),(VLOOKUP($C6,'V-LOOKUP'!$C$4:$M$59,7,FALSE)),"0") -> 0 | CF6: =IF(AND($C6<>"",$J6<>""),(VLOOKUP($C6,'V-LOOKUP'!$C$4:$M$59,8,FALSE)),"0") -> 0 | CG6: =IF(AND($C6<>"",$J6<>""),(VLOOKUP($C6,'V-LOOKUP'!$C$4:$M$59,9,FALSE)),"0") -> 0 | CH6: =IF(AND($C6<>"",$J6<>""),(VLOOKUP($C6,'V-LOOKUP'!$C$4:$M$59,10,FALSE)),"0") -> 0 | CI6: =IF(AND($C6<>"",$J6<>""),(VLOOKUP($C6,'V-LOOKUP'!$C$4:$M$59,11,FALSE)),"0") -> 0 | CJ6: =IF(AND($C6<>"",$J6<>""),(VLOOKUP($C6,'V-LOOKUP'!$C$4:$N$59,12,FALSE)),"0") -> 0 | CK6: =IF(AND($C6<>"",K6<>""),(VLOOKUP($C6,'V-LOOKUP'!$C$4:$M$59,4,FALSE)),"0") -> 0 | CL6: =IF(AND($C6<>"",$K6<>""),(VLOOKUP($C6,'V-LOOKUP'!$C$4:$M$59,5,FALSE)),"0") -> 0 | CM6: =IF(AND($C6<>"",$K6<>""),(VLOOKUP($C6,'V-LOOKUP'!$C$4:$M$59,6,FALSE)),"0") -> 0 | CN6: =IF(AND($C6<>"",$K6<>""),(VLOOKUP($C6,'V-LOOKUP'!$C$4:$M$59,7,FALSE)),"0") -> 0 | CO6: =IF(AND($C6<>"",$K6<>""),(VLOOKUP($C6,'V-LOOKUP'!$C$4:$M$59,8,FALSE)),"0") -> 0 | CP6: =IF(AND($C6<>"",$K6<>""),(VLOOKUP($C6,'V-LOOKUP'!$C$4:$M$59,9,FALSE)),"0") -> 0 | CQ6: =IF(AND($C6<>"",$K6<>""),(VLOOKUP($C6,'V-LOOKUP'!$C$4:$M$59,10,FALSE)),"0") -> 0 | CR6: =IF(AND($C6<>"",$K6<>""),(VLOOKUP($C6,'V-LOOKUP'!$C$4:$M$59,11,FALSE)),"0") -> 0 | CS6: =IF(AND($C6<>"",$K6<>""),(VLOOKUP($C6,'V-LOOKUP'!$C$4:$N$59,12,FALSE)),"0") -> 0 | CT6: =IF(AND($C6<>"",L6<>""),(VLOOKUP($C6,'V-LOOKUP'!$C$4:$M$59,4,FALSE)),"0") -> 0 | CU6: =IF(AND($C6<>"",$L6<>""),(VLOOKUP($C6,'V-LOOKUP'!$C$4:$M$59,5,FALSE)),"0") -> 0 | CV6: =IF(AND($C6<>"",$L6<>""),(VLOOKUP($C6,'V-LOOKUP'!$C$4:$M$59,6,FALSE)),"0") -> 0 | CW6: =IF(AND($C6<>"",$L6<>""),(VLOOKUP($C6,'V-LOOKUP'!$C$4:$M$59,7,FALSE)),"0") -> 0 | CX6: =IF(AND($C6<>"",$L6<>""),(VLOOKUP($C6,'V-LOOKUP'!$C$4:$M$59,8,FALSE)),"0") -> 0 | CY6: =IF(AND($C6<>"",$L6<>""),(VLOOKUP($C6,'V-LOOKUP'!$C$4:$M$59,9,FALSE)),"0") -> 0 | CZ6: =IF(AND($C6<>"",$L6<>""),(VLOOKUP($C6,'V-LOOKUP'!$C$4:$M$59,10,FALSE)),"0") -> 0 | DA6: =IF(AND($C6<>"",$L6<>""),(VLOOKUP($C6,'V-LOOKUP'!$C$4:$M$59,11,FALSE)),"0") -> 0 | DB6: =IF(AND($C6<>"",$L6<>""),(VLOOKUP($C6,'V-LOOKUP'!$C$4:$N$59,12,FALSE)),"0") -> 0 | DC6: =IF(AND($C6<>"",M6<>""),(VLOOKUP($C6,'V-LOOKUP'!$C$4:$M$59,4,FALSE)),"0") -> 0 | DD6: =IF(AND($C6<>"",$M6<>""),(VLOOKUP($C6,'V-LOOKUP'!$C$4:$M$59,5,FALSE)),"0") -> 0 | DE6: =IF(AND($C6<>"",$M6<>""),(VLOOKUP($C6,'V-LOOKUP'!$C$4:$M$59,6,FALSE)),"0") -> 0 | DF6: =IF(AND($C6<>"",$M6<>""),(VLOOKUP($C6,'V-LOOKUP'!$C$4:$M$59,7,FALSE)),"0") -> 0 | DG6: =IF(AND($C6<>"",$M6<>""),(VLOOKUP($C6,'V-LOOKUP'!$C$4:$M$59,8,FALSE)),"0") -> 0 | DH6: =IF(AND($C6<>"",$M6<>""),(VLOOKUP($C6,'V-LOOKUP'!$C$4:$M$59,9,FALSE)),"0") -> 0 | DI6: =IF(AND($C6<>"",$M6<>""),(VLOOKUP($C6,'V-LOOKUP'!$C$4:$M$59,10,FALSE)),"0") -> 0 | DJ6: =IF(AND($C6<>"",$M6<>""),(VLOOKUP($C6,'V-LOOKUP'!$C$4:$M$59,11,FALSE)),"0") -> 0 | DK6: =IF(AND($C6<>"",$M6<>""),(VLOOKUP($C6,'V-LOOKUP'!$C$4:$N$59,12,FALSE)),"0") -> 0 | DL6: =IF(AND($C6<>"",$N6<>""),(VLOOKUP($C6,'V-LOOKUP'!$C$4:$M$59,4,FALSE)),"0") -> 0 | DM6: =IF(AND($C6<>"",$N6<>""),(VLOOKUP($C6,'V-LOOKUP'!$C$4:$M$59,5,FALSE)),"0") -> 0 | DN6: =IF(AND($C6<>"",$N6<>""),(VLOOKUP($C6,'V-LOOKUP'!$C$4:$M$59,6,FALSE)),"0") -> 0 | DO6: =IF(AND($C6<>"",$N6<>""),(VLOOKUP($C6,'V-LOOKUP'!$C$4:$M$59,7,FALSE)),"0") -> 0 | DP6: =IF(AND($C6<>"",$N6<>""),(VLOOKUP($C6,'V-LOOKUP'!$C$4:$M$59,8,FALSE)),"0") -> 0 | DQ6: =IF(AND($C6<>"",$N6<>""),(VLOOKUP($C6,'V-LOOKUP'!$C$4:$M$59,9,FALSE)),"0") -> 0 | DR6: =IF(AND($C6<>"",$N6<>""),(VLOOKUP($C6,'V-LOOKUP'!$C$4:$M$59,10,FALSE)),"0") -> 0 | DS6: =IF(AND($C6<>"",$N6<>""),(VLOOKUP($C6,'V-LOOKUP'!$C$4:$M$59,11,FALSE)),"0") -> 0 | DT6: =IF(AND($C6<>"",$N6<>""),(VLOOKUP($C6,'V-LOOKUP'!$C$4:$N$59,12,FALSE)),"0") -> 0 | DU6: =IF(AND($C6<>"",O6<>""),(VLOOKUP($C6,'V-LOOKUP'!$C$4:$M$59,4,FALSE)),"0") -> 0 | DV6: =IF(AND($C6<>"",$O6<>""),(VLOOKUP($C6,'V-LOOKUP'!$C$4:$M$59,5,FALSE)),"0") -> 0 | DW6: =IF(AND($C6<>"",$O6<>""),(VLOOKUP($C6,'V-LOOKUP'!$C$4:$M$59,6,FALSE)),"0") -> 0 | DX6: =IF(AND($C6<>"",$O6<>""),(VLOOKUP($C6,'V-LOOKUP'!$C$4:$M$59,7,FALSE)),"0") -> 0 | DY6: =IF(AND($C6<>"",$O6<>""),(VLOOKUP($C6,'V-LOOKUP'!$C$4:$M$59,8,FALSE)),"0") -> 0 | DZ6: =IF(AND($C6<>"",$O6<>""),(VLOOKUP($C6,'V-LOOKUP'!$C$4:$M$59,9,FALSE)),"0") -> 0 | EA6: =IF(AND($C6<>"",$O6<>""),(VLOOKUP($C6,'V-LOOKUP'!$C$4:$M$59,10,FALSE)),"0") -> 0 | EB6: =IF(AND($C6<>"",$O6<>""),(VLOOKUP($C6,'V-LOOKUP'!$C$4:$M$59,11,FALSE)),"0") -> 0 | EC6: =IF(AND($C6<>"",$O6<>""),(VLOOKUP($C6,'V-LOOKUP'!$C$4:$N$59,12,FALSE)),"0") -> 0 | ED6: =IF(AND($C6<>"",P6<>""),(VLOOKUP($C6,'V-LOOKUP'!$C$4:$M$59,4,FALSE)),"0") -> 0 | EE6: =IF(AND($C6<>"",$P6<>""),(VLOOKUP($C6,'V-LOOKUP'!$C$4:$M$59,5,FALSE)),"0") -> 0 | EF6: =IF(AND($C6<>"",$P6<>""),(VLOOKUP($C6,'V-LOOKUP'!$C$4:$M$59,6,FALSE)),"0") -> 0 | EG6: =IF(AND($C6<>"",$P6<>""),(VLOOKUP($C6,'V-LOOKUP'!$C$4:$M$59,7,FALSE)),"0") -> 0 | EH6: =IF(AND($C6<>"",$P6<>""),(VLOOKUP($C6,'V-LOOKUP'!$C$4:$M$59,8,FALSE)),"0") -> 0 | EI6: =IF(AND($C6<>"",$P6<>""),(VLOOKUP($C6,'V-LOOKUP'!$C$4:$M$59,9,FALSE)),"0") -> 0 | EJ6: =IF(AND($C6<>"",$P6<>""),(VLOOKUP($C6,'V-LOOKUP'!$C$4:$M$59,10,FALSE)),"0") -> 0 | EK6: =IF(AND($C6<>"",$P6<>""),(VLOOKUP($C6,'V-LOOKUP'!$C$4:$M$59,11,FALSE)),"0") -> 0 | EL6: =IF(AND($C6<>"",$P6<>""),(VLOOKUP($C6,'V-LOOKUP'!$C$4:$N$59,12,FALSE)),"0") -> 0 | EM6: =IF(AND($C6<>"",Q6<>""),(VLOOKUP($C6,'V-LOOKUP'!$C$4:$M$59,4,FALSE)),"0") -> 0 | EN6: =IF(AND($C6<>"",$Q6<>""),(VLOOKUP($C6,'V-LOOKUP'!$C$4:$M$59,5,FALSE)),"0") -> 0 | EO6: =IF(AND($C6<>"",$Q6<>""),(VLOOKUP($C6,'V-LOOKUP'!$C$4:$M$59,6,FALSE)),"0") -> 0 | EP6: =IF(AND($C6<>"",$Q6<>""),(VLOOKUP($C6,'V-LOOKUP'!$C$4:$M$59,7,FALSE)),"0") -> 0 | EQ6: =IF(AND($C6<>"",$Q6<>""),(VLOOKUP($C6,'V-LOOKUP'!$C$4:$M$59,8,FALSE)),"0") -> 0 | ER6: =IF(AND($C6<>"",$Q6<>""),(VLOOKUP($C6,'V-LOOKUP'!$C$4:$M$59,9,FALSE)),"0") -> 0 | ES6: =IF(AND($C6<>"",$Q6<>""),(VLOOKUP($C6,'V-LOOKUP'!$C$4:$M$59,10,FALSE)),"0") -> 0 | ET6: =IF(AND($C6<>"",$Q6<>""),(VLOOKUP($C6,'V-LOOKUP'!$C$4:$M$59,11,FALSE)),"0") -> 0 | EU6: =IF(AND($C6<>"",$Q6<>""),(VLOOKUP($C6,'V-LOOKUP'!$C$4:$N$59,12,FALSE)),"0") -> 0 | EV6: =IF(AND($C6<>"",R6<>""),(VLOOKUP($C6,'V-LOOKUP'!$C$4:$M$59,4,FALSE)),"0") -> 0 | EW6: =IF(AND($C6<>"",$R6<>""),(VLOOKUP($C6,'V-LOOKUP'!$C$4:$M$59,5,FALSE)),"0") -> 0 | EX6: =IF(AND($C6<>"",$R6<>""),(VLOOKUP($C6,'V-LOOKUP'!$C$4:$M$59,6,FALSE)),"0") -> 0 | EY6: =IF(AND($C6<>"",$R6<>""),(VLOOKUP($C6,'V-LOOKUP'!$C$4:$M$59,7,FALSE)),"0") -> 0 | EZ6: =IF(AND($C6<>"",$R6<>""),(VLOOKUP($C6,'V-LOOKUP'!$C$4:$M$59,8,FALSE)),"0") -> 0 | FA6: =IF(AND($C6<>"",$R6<>""),(VLOOKUP($C6,'V-LOOKUP'!$C$4:$M$59,9,FALSE)),"0") -> 0 | FB6: =IF(AND($C6<>"",$R6<>""),(VLOOKUP($C6,'V-LOOKUP'!$C$4:$M$59,10,FALSE)),"0") -> 0 | FC6: =IF(AND($C6<>"",$R6<>""),(VLOOKUP($C6,'V-LOOKUP'!$C$4:$M$59,11,FALSE)),"0") -> 0 | FD6: =IF(AND($C6<>"",$R6<>""),(VLOOKUP($C6,'V-LOOKUP'!$C$4:$N$59,12,FALSE)),"0") -> 0 | FE6: =IF(AND($C6<>"",S6<>""),(VLOOKUP($C6,'V-LOOKUP'!$C$4:$M$59,4,FALSE)),"0") -> 0 | FF6: =IF(AND($C6<>"",$S6<>""),(VLOOKUP($C6,'V-LOOKUP'!$C$4:$M$59,5,FALSE)),"0") -> 0 | FG6: =IF(AND($C6<>"",$S6<>""),(VLOOKUP($C6,'V-LOOKUP'!$C$4:$M$59,6,FALSE)),"0") -> 0 | FH6: =IF(AND($C6<>"",$S6<>""),(VLOOKUP($C6,'V-LOOKUP'!$C$4:$M$59,7,FALSE)),"0") -> 0 | FI6: =IF(AND($C6<>"",$S6<>""),(VLOOKUP($C6,'V-LOOKUP'!$C$4:$M$59,8,FALSE)),"0") -> 0 | FJ6: =IF(AND($C6<>"",$S6<>""),(VLOOKUP($C6,'V-LOOKUP'!$C$4:$M$59,9,FALSE)),"0") -> 0 | FK6: =IF(AND($C6<>"",$S6<>""),(VLOOKUP($C6,'V-LOOKUP'!$C$4:$M$59,10,FALSE)),"0") -> 0 | FL6: =IF(AND($C6<>"",$S6<>""),(VLOOKUP($C6,'V-LOOKUP'!$C$4:$M$59,11,FALSE)),"0") -> 0 | FM6: =IF(AND($C6<>"",$S6<>""),(VLOOKUP($C6,'V-LOOKUP'!$C$4:$N$59,12,FALSE)),"0") -> 0 | FN6: =IF(AND($C6<>"",T6<>""),(VLOOKUP($C6,'V-LOOKUP'!$C$4:$M$59,4,FALSE)),"0") -> 0 | FO6: =IF(AND($C6<>"",$T6<>""),(VLOOKUP($C6,'V-LOOKUP'!$C$4:$M$59,5,FALSE)),"0") -> 0 | FP6: =IF(AND($C6<>"",$T6<>""),(VLOOKUP($C6,'V-LOOKUP'!$C$4:$M$59,6,FALSE)),"0") -> 0 | FQ6: =IF(AND($C6<>"",$T6<>""),(VLOOKUP($C6,'V-LOOKUP'!$C$4:$M$59,7,FALSE)),"0") -> 0 | FR6: =IF(AND($C6<>"",$T6<>""),(VLOOKUP($C6,'V-LOOKUP'!$C$4:$M$59,8,FALSE)),"0") -> 0 | FS6: =IF(AND($C6<>"",$T6<>""),(VLOOKUP($C6,'V-LOOKUP'!$C$4:$M$59,9,FALSE)),"0") -> 0 | FT6: =IF(AND($C6<>"",$T6<>""),(VLOOKUP($C6,'V-LOOKUP'!$C$4:$M$59,10,FALSE)),"0") -> 0 | FU6: =IF(AND($C6<>"",$T6<>""),(VLOOKUP($C6,'V-LOOKUP'!$C$4:$M$59,11,FALSE)),"0") -> 0 | FV6: =IF(AND($C6<>"",$T6<>""),(VLOOKUP($C6,'V-LOOKUP'!$C$4:$N$59,12,FALSE)),"0") -> 0 | FW6: =IF(AND($C6<>"",U6<>""),(VLOOKUP($C6,'V-LOOKUP'!$C$4:$M$59,4,FALSE)),"0") -> 0 | FX6: =IF(AND($C6<>"",$U6<>""),(VLOOKUP($C6,'V-LOOKUP'!$C$4:$M$59,5,FALSE)),"0") -> 0 | FY6: =IF(AND($C6<>"",$U6<>""),(VLOOKUP($C6,'V-LOOKUP'!$C$4:$M$59,6,FALSE)),"0") -> 0 | FZ6: =IF(AND($C6<>"",$U6<>""),(VLOOKUP($C6,'V-LOOKUP'!$C$4:$M$59,7,FALSE)),"0") -> 0 | GA6: =IF(AND($C6<>"",$U6<>""),(VLOOKUP($C6,'V-LOOKUP'!$C$4:$M$59,8,FALSE)),"0") -> 0 | GB6: =IF(AND($C6<>"",$U6<>""),(VLOOKUP($C6,'V-LOOKUP'!$C$4:$M$59,9,FALSE)),"0") -> 0 | GC6: =IF(AND($C6<>"",$U6<>""),(VLOOKUP($C6,'V-LOOKUP'!$C$4:$M$59,10,FALSE)),"0") -> 0 | GD6: =IF(AND($C6<>"",$U6<>""),(VLOOKUP($C6,'V-LOOKUP'!$C$4:$M$59,11,FALSE)),"0") -> 0 | GE6: =IF(AND($C6<>"",$U6<>""),(VLOOKUP($C6,'V-LOOKUP'!$C$4:$N$59,12,FALSE)),"0") -> 0 | GF6: =IF(AND($C6<>"",V6<>""),(VLOOKUP($C6,'V-LOOKUP'!$C$4:$M$59,4,FALSE)),"0") -> 0 | GG6: =IF(AND($C6<>"",$V6<>""),(VLOOKUP($C6,'V-LOOKUP'!$C$4:$M$59,5,FALSE)),"0") -> 0 | GH6: =IF(AND($C6<>"",$V6<>""),(VLOOKUP($C6,'V-LOOKUP'!$C$4:$M$59,6,FALSE)),"0") -> 0 | GI6: =IF(AND($C6<>"",$V6<>""),(VLOOKUP($C6,'V-LOOKUP'!$C$4:$M$59,7,FALSE)),"0") -> 0 | GJ6: =IF(AND($C6<>"",$V6<>""),(VLOOKUP($C6,'V-LOOKUP'!$C$4:$M$59,8,FALSE)),"0") -> 0 | GK6: =IF(AND($C6<>"",$V6<>""),(VLOOKUP($C6,'V-LOOKUP'!$C$4:$M$59,9,FALSE)),"0") -> 0 | GL6: =IF(AND($C6<>"",$V6<>""),(VLOOKUP($C6,'V-LOOKUP'!$C$4:$M$59,10,FALSE)),"0") -> 0 | GM6: =IF(AND($C6<>"",$V6<>""),(VLOOKUP($C6,'V-LOOKUP'!$C$4:$M$59,11,FALSE)),"0") -> 0 | GN6: =IF(AND($C6<>"",$V6<>""),(VLOOKUP($C6,'V-LOOKUP'!$C$4:$N$59,12,FALSE)),"0") -> 0 | GO6: =IF(AND($C6<>"",W6<>""),(VLOOKUP($C6,'V-LOOKUP'!$C$4:$M$59,4,FALSE)),"0") -> 0 | GP6: =IF(AND($C6<>"",$W6<>""),(VLOOKUP($C6,'V-LOOKUP'!$C$4:$M$59,5,FALSE)),"0") -> 0 | GQ6: =IF(AND($C6<>"",$W6<>""),(VLOOKUP($C6,'V-LOOKUP'!$C$4:$M$59,6,FALSE)),"0") -> 0 | GR6: =IF(AND($C6<>"",$W6<>""),(VLOOKUP($C6,'V-LOOKUP'!$C$4:$M$59,7,FALSE)),"0") -> 0 | GS6: =IF(AND($C6<>"",$W6<>""),(VLOOKUP($C6,'V-LOOKUP'!$C$4:$M$59,8,FALSE)),"0") -> 0 | GT6: =IF(AND($C6<>"",$W6<>""),(VLOOKUP($C6,'V-LOOKUP'!$C$4:$M$59,9,FALSE)),"0") -> 0 | GU6: =IF(AND($C6<>"",$W6<>""),(VLOOKUP($C6,'V-LOOKUP'!$C$4:$M$59,10,FALSE)),"0") -> 0 | GV6: =IF(AND($C6<>"",$W6<>""),(VLOOKUP($C6,'V-LOOKUP'!$C$4:$M$59,11,FALSE)),"0") -> 0 | GW6: =IF(AND($C6<>"",$W6<>""),(VLOOKUP($C6,'V-LOOKUP'!$C$4:$N$59,12,FALSE)),"0") -> 0
Z7: =IF(AND($C7<>"",$D7<>""),(VLOOKUP($C7,'V-LOOKUP'!$C$4:$M$59,4,FALSE)),"0") -> 0 | AA7: =IF(AND($C7<>"",$D7<>""),(VLOOKUP($C7,'V-LOOKUP'!$C$4:$M$59,5,FALSE)),"0") -> 0 | AB7: =IF(AND($C7<>"",$D7<>""),(VLOOKUP($C7,'V-LOOKUP'!$C$4:$M$59,6,FALSE)),"0") -> 0 | AC7: =IF(AND($C7<>"",$D7<>""),(VLOOKUP($C7,'V-LOOKUP'!$C$4:$M$59,7,FALSE)),"0") -> 0 | AD7: =IF(AND($C7<>"",$D7<>""),(VLOOKUP($C7,'V-LOOKUP'!$C$4:$M$59,8,FALSE)),"0") -> 0 | AE7: =IF(AND($C7<>"",$D7<>""),(VLOOKUP($C7,'V-LOOKUP'!$C$4:$M$59,9,FALSE)),"0") -> 0 | AF7: =IF(AND($C7<>"",$D7<>""),(VLOOKUP($C7,'V-LOOKUP'!$C$4:$M$59,10,FALSE)),"0") -> 0 | AG7: =IF(AND($C7<>"",$D7<>""),(VLOOKUP($C7,'V-LOOKUP'!$C$4:$M$59,11,FALSE)),"0") -> 0 | AH7: =IF(AND($C7<>"",$D7<>""),(VLOOKUP($C7,'V-LOOKUP'!$C$4:$N$59,12,FALSE)),"0") -> 0 | AI7: =IF(AND($C7<>"",E7<>""),(VLOOKUP($C7,'V-LOOKUP'!$C$4:$M$59,4,FALSE)),"0") -> 0 | AJ7: =IF(AND($C7<>"",$E7<>""),(VLOOKUP($C7,'V-LOOKUP'!$C$4:$M$59,5,FALSE)),"0") -> 0 | AK7: =IF(AND($C7<>"",$E7<>""),(VLOOKUP($C7,'V-LOOKUP'!$C$4:$M$59,6,FALSE)),"0") -> 0 | AL7: =IF(AND($C7<>"",$E7<>""),(VLOOKUP($C7,'V-LOOKUP'!$C$4:$M$59,7,FALSE)),"0") -> 0 | AM7: =IF(AND($C7<>"",$E7<>""),(VLOOKUP($C7,'V-LOOKUP'!$C$4:$M$59,8,FALSE)),"0") -> 0 | AN7: =IF(AND($C7<>"",$E7<>""),(VLOOKUP($C7,'V-LOOKUP'!$C$4:$M$59,9,FALSE)),"0") -> 0 | AO7: =IF(AND($C7<>"",$E7<>""),(VLOOKUP($C7,'V-LOOKUP'!$C$4:$M$59,10,FALSE)),"0") -> 0 | AP7: =IF(AND($C7<>"",$E7<>""),(VLOOKUP($C7,'V-LOOKUP'!$C$4:$M$59,11,FALSE)),"0") -> 0 | AQ7: =IF(AND($C7<>"",$E7<>""),(VLOOKUP($C7,'V-LOOKUP'!$C$4:$N$59,12,FALSE)),"0") -> 0 | AR7: =IF(AND($C7<>"",$F7<>""),(VLOOKUP($C7,'V-LOOKUP'!$C$4:$M$59,4,FALSE)),"0") -> 0 | AS7: =IF(AND($C7<>"",$F7<>""),(VLOOKUP($C7,'V-LOOKUP'!$C$4:$M$59,5,FALSE)),"0") -> 0 | AT7: =IF(AND($C7<>"",$F7<>""),(VLOOKUP($C7,'V-LOOKUP'!$C$4:$M$59,6,FALSE)),"0") -> 0 | AU7: =IF(AND($C7<>"",$F7<>""),(VLOOKUP($C7,'V-LOOKUP'!$C$4:$M$59,7,FALSE)),"0") -> 0 | AV7: =IF(AND($C7<>"",$F7<>""),(VLOOKUP($C7,'V-LOOKUP'!$C$4:$M$59,8,FALSE)),"0") -> 0 | AW7: =IF(AND($C7<>"",$F7<>""),(VLOOKUP($C7,'V-LOOKUP'!$C$4:$M$59,9,FALSE)),"0") -> 0 | AX7: =IF(AND($C7<>"",$F7<>""),(VLOOKUP($C7,'V-LOOKUP'!$C$4:$M$59,10,FALSE)),"0") -> 0 | AY7: =IF(AND($C7<>"",$F7<>""),(VLOOKUP($C7,'V-LOOKUP'!$C$4:$M$59,11,FALSE)),"0") -> 0 | AZ7: =IF(AND($C7<>"",$F7<>""),(VLOOKUP($C7,'V-LOOKUP'!$C$4:$N$59,12,FALSE)),"0") -> 0 | BA7: =IF(AND($C7<>"",G7<>""),(VLOOKUP($C7,'V-LOOKUP'!$C$4:$M$59,4,FALSE)),"0") -> 0 | BB7: =IF(AND($C7<>"",$G7<>""),(VLOOKUP($C7,'V-LOOKUP'!$C$4:$M$59,5,FALSE)),"0") -> 0 | BC7: =IF(AND($C7<>"",$G7<>""),(VLOOKUP($C7,'V-LOOKUP'!$C$4:$M$59,6,FALSE)),"0") -> 0 | BD7: =IF(AND($C7<>"",$G7<>""),(VLOOKUP($C7,'V-LOOKUP'!$C$4:$M$59,7,FALSE)),"0") -> 0 | BE7: =IF(AND($C7<>"",$G7<>""),(VLOOKUP($C7,'V-LOOKUP'!$C$4:$M$59,8,FALSE)),"0") -> 0 | BF7: =IF(AND($C7<>"",$G7<>""),(VLOOKUP($C7,'V-LOOKUP'!$C$4:$M$59,9,FALSE)),"0") -> 0 | BG7: =IF(AND($C7<>"",$G7<>""),(VLOOKUP($C7,'V-LOOKUP'!$C$4:$M$59,10,FALSE)),"0") -> 0 | BH7: =IF(AND($C7<>"",$G7<>""),(VLOOKUP($C7,'V-LOOKUP'!$C$4:$M$59,11,FALSE)),"0") -> 0 | BI7: =IF(AND($C7<>"",$G7<>""),(VLOOKUP($C7,'V-LOOKUP'!$C$4:$N$59,12,FALSE)),"0") -> 0 | BJ7: =IF(AND($C7<>"",H7<>""),(VLOOKUP($C7,'V-LOOKUP'!$C$4:$M$59,4,FALSE)),"0") -> 0 | BK7: =IF(AND($C7<>"",$G7<>""),(VLOOKUP($C7,'V-LOOKUP'!$C$4:$M$59,5,FALSE)),"0") -> 0 | BL7: =IF(AND($C7<>"",$H7<>""),(VLOOKUP($C7,'V-LOOKUP'!$C$4:$M$59,6,FALSE)),"0") -> 0 | BM7: =IF(AND($C7<>"",$H7<>""),(VLOOKUP($C7,'V-LOOKUP'!$C$4:$M$59,7,FALSE)),"0") -> 0 | BN7: =IF(AND($C7<>"",$H7<>""),(VLOOKUP($C7,'V-LOOKUP'!$C$4:$M$59,8,FALSE)),"0") -> 0 | BO7: =IF(AND($C7<>"",$H7<>""),(VLOOKUP($C7,'V-LOOKUP'!$C$4:$M$59,9,FALSE)),"0") -> 0 | BP7: =IF(AND($C7<>"",$H7<>""),(VLOOKUP($C7,'V-LOOKUP'!$C$4:$M$59,10,FALSE)),"0") -> 0 | BQ7: =IF(AND($C7<>"",$H7<>""),(VLOOKUP($C7,'V-LOOKUP'!$C$4:$M$59,11,FALSE)),"0") -> 0 | BR7: =IF(AND($C7<>"",$H7<>""),(VLOOKUP($C7,'V-LOOKUP'!$C$4:$N$59,12,FALSE)),"0") -> 0 | BS7: =IF(AND($C7<>"",I7<>""),(VLOOKUP($C7,'V-LOOKUP'!$C$4:$M$59,4,FALSE)),"0") -> 0 | BT7: =IF(AND($C7<>"",$I7<>""),(VLOOKUP($C7,'V-LOOKUP'!$C$4:$M$59,5,FALSE)),"0") -> 0 | BU7: =IF(AND($C7<>"",$I7<>""),(VLOOKUP($C7,'V-LOOKUP'!$C$4:$M$59,6,FALSE)),"0") -> 0 | BV7: =IF(AND($C7<>"",$I7<>""),(VLOOKUP($C7,'V-LOOKUP'!$C$4:$M$59,7,FALSE)),"0") -> 0 | BW7: =IF(AND($C7<>"",$I7<>""),(VLOOKUP($C7,'V-LOOKUP'!$C$4:$M$59,8,FALSE)),"0") -> 0 | BX7: =IF(AND($C7<>"",$I7<>""),(VLOOKUP($C7,'V-LOOKUP'!$C$4:$M$59,9,FALSE)),"0") -> 0 | BY7: =IF(AND($C7<>"",$I7<>""),(VLOOKUP($C7,'V-LOOKUP'!$C$4:$M$59,10,FALSE)),"0") -> 0 | BZ7: =IF(AND($C7<>"",$I7<>""),(VLOOKUP($C7,'V-LOOKUP'!$C$4:$M$59,11,FALSE)),"0") -> 0 | CA7: =IF(AND($C7<>"",$I7<>""),(VLOOKUP($C7,'V-LOOKUP'!$C$4:$N$59,12,FALSE)),"0") -> 0 | CB7: =IF(AND($C7<>"",J7<>""),(VLOOKUP($C7,'V-LOOKUP'!$C$4:$M$59,4,FALSE)),"0") -> 0 | CC7: =IF(AND($C7<>"",$J7<>""),(VLOOKUP($C7,'V-LOOKUP'!$C$4:$M$59,5,FALSE)),"0") -> 0 | CD7: =IF(AND($C7<>"",$J7<>""),(VLOOKUP($C7,'V-LOOKUP'!$C$4:$M$59,6,FALSE)),"0") -> 0 | CE7: =IF(AND($C7<>"",$J7<>""),(VLOOKUP($C7,'V-LOOKUP'!$C$4:$M$59,7,FALSE)),"0") -> 0 | CF7: =IF(AND($C7<>"",$J7<>""),(VLOOKUP($C7,'V-LOOKUP'!$C$4:$M$59,8,FALSE)),"0") -> 0 | CG7: =IF(AND($C7<>"",$J7<>""),(VLOOKUP($C7,'V-LOOKUP'!$C$4:$M$59,9,FALSE)),"0") -> 0 | CH7: =IF(AND($C7<>"",$J7<>""),(VLOOKUP($C7,'V-LOOKUP'!$C$4:$M$59,10,FALSE)),"0") -> 0 | CI7: =IF(AND($C7<>"",$J7<>""),(VLOOKUP($C7,'V-LOOKUP'!$C$4:$M$59,11,FALSE)),"0") -> 0 | CJ7: =IF(AND($C7<>"",$J7<>""),(VLOOKUP($C7,'V-LOOKUP'!$C$4:$N$59,12,FALSE)),"0") -> 0 | CK7: =IF(AND($C7<>"",K7<>""),(VLOOKUP($C7,'V-LOOKUP'!$C$4:$M$59,4,FALSE)),"0") -> 0 | CL7: =IF(AND($C7<>"",$K7<>""),(VLOOKUP($C7,'V-LOOKUP'!$C$4:$M$59,5,FALSE)),"0") -> 0 | CM7: =IF(AND($C7<>"",$K7<>""),(VLOOKUP($C7,'V-LOOKUP'!$C$4:$M$59,6,FALSE)),"0") -> 0 | CN7: =IF(AND($C7<>"",$K7<>""),(VLOOKUP($C7,'V-LOOKUP'!$C$4:$M$59,7,FALSE)),"0") -> 0 | CO7: =IF(AND($C7<>"",$K7<>""),(VLOOKUP($C7,'V-LOOKUP'!$C$4:$M$59,8,FALSE)),"0") -> 0 | CP7: =IF(AND($C7<>"",$K7<>""),(VLOOKUP($C7,'V-LOOKUP'!$C$4:$M$59,9,FALSE)),"0") -> 0 | CQ7: =IF(AND($C7<>"",$K7<>""),(VLOOKUP($C7,'V-LOOKUP'!$C$4:$M$59,10,FALSE)),"0") -> 0 | CR7: =IF(AND($C7<>"",$K7<>""),(VLOOKUP($C7,'V-LOOKUP'!$C$4:$M$59,11,FALSE)),"0") -> 0 | CS7: =IF(AND($C7<>"",$K7<>""),(VLOOKUP($C7,'V-LOOKUP'!$C$4:$N$59,12,FALSE)),"0") -> 0 | CT7: =IF(AND($C7<>"",L7<>""),(VLOOKUP($C7,'V-LOOKUP'!$C$4:$M$59,4,FALSE)),"0") -> 0 | CU7: =IF(AND($C7<>"",$L7<>""),(VLOOKUP($C7,'V-LOOKUP'!$C$4:$M$59,5,FALSE)),"0") -> 0 | CV7: =IF(AND($C7<>"",$L7<>""),(VLOOKUP($C7,'V-LOOKUP'!$C$4:$M$59,6,FALSE)),"0") -> 0 | CW7: =IF(AND($C7<>"",$L7<>""),(VLOOKUP($C7,'V-LOOKUP'!$C$4:$M$59,7,FALSE)),"0") -> 0 | CX7: =IF(AND($C7<>"",$L7<>""),(VLOOKUP($C7,'V-LOOKUP'!$C$4:$M$59,8,FALSE)),"0") -> 0 | CY7: =IF(AND($C7<>"",$L7<>""),(VLOOKUP($C7,'V-LOOKUP'!$C$4:$M$59,9,FALSE)),"0") -> 0 | CZ7: =IF(AND($C7<>"",$L7<>""),(VLOOKUP($C7,'V-LOOKUP'!$C$4:$M$59,10,FALSE)),"0") -> 0 | DA7: =IF(AND($C7<>"",$L7<>""),(VLOOKUP($C7,'V-LOOKUP'!$C$4:$M$59,11,FALSE)),"0") -> 0 | DB7: =IF(AND($C7<>"",$L7<>""),(VLOOKUP($C7,'V-LOOKUP'!$C$4:$N$59,12,FALSE)),"0") -> 0 | DC7: =IF(AND($C7<>"",M7<>""),(VLOOKUP($C7,'V-LOOKUP'!$C$4:$M$59,4,FALSE)),"0") -> 0 | DD7: =IF(AND($C7<>"",$M7<>""),(VLOOKUP($C7,'V-LOOKUP'!$C$4:$M$59,5,FALSE)),"0") -> 0 | DE7: =IF(AND($C7<>"",$M7<>""),(VLOOKUP($C7,'V-LOOKUP'!$C$4:$M$59,6,FALSE)),"0") -> 0 | DF7: =IF(AND($C7<>"",$M7<>""),(VLOOKUP($C7,'V-LOOKUP'!$C$4:$M$59,7,FALSE)),"0") -> 0 | DG7: =IF(AND($C7<>"",$M7<>""),(VLOOKUP($C7,'V-LOOKUP'!$C$4:$M$59,8,FALSE)),"0") -> 0 | DH7: =IF(AND($C7<>"",$M7<>""),(VLOOKUP($C7,'V-LOOKUP'!$C$4:$M$59,9,FALSE)),"0") -> 0 | DI7: =IF(AND($C7<>"",$M7<>""),(VLOOKUP($C7,'V-LOOKUP'!$C$4:$M$59,10,FALSE)),"0") -> 0 | DJ7: =IF(AND($C7<>"",$M7<>""),(VLOOKUP($C7,'V-LOOKUP'!$C$4:$M$59,11,FALSE)),"0") -> 0 | DK7: =IF(AND($C7<>"",$M7<>""),(VLOOKUP($C7,'V-LOOKUP'!$C$4:$N$59,12,FALSE)),"0") -> 0 | DL7: =IF(AND($C7<>"",$N7<>""),(VLOOKUP($C7,'V-LOOKUP'!$C$4:$M$59,4,FALSE)),"0") -> 0 | DM7: =IF(AND($C7<>"",$N7<>""),(VLOOKUP($C7,'V-LOOKUP'!$C$4:$M$59,5,FALSE)),"0") -> 0 | DN7: =IF(AND($C7<>"",$N7<>""),(VLOOKUP($C7,'V-LOOKUP'!$C$4:$M$59,6,FALSE)),"0") -> 0 | DO7: =IF(AND($C7<>"",$N7<>""),(VLOOKUP($C7,'V-LOOKUP'!$C$4:$M$59,7,FALSE)),"0") -> 0 | DP7: =IF(AND($C7<>"",$N7<>""),(VLOOKUP($C7,'V-LOOKUP'!$C$4:$M$59,8,FALSE)),"0") -> 0 | DQ7: =IF(AND($C7<>"",$N7<>""),(VLOOKUP($C7,'V-LOOKUP'!$C$4:$M$59,9,FALSE)),"0") -> 0 | DR7: =IF(AND($C7<>"",$N7<>""),(VLOOKUP($C7,'V-LOOKUP'!$C$4:$M$59,10,FALSE)),"0") -> 0 | DS7: =IF(AND($C7<>"",$N7<>""),(VLOOKUP($C7,'V-LOOKUP'!$C$4:$M$59,11,FALSE)),"0") -> 0 | DT7: =IF(AND($C7<>"",$N7<>""),(VLOOKUP($C7,'V-LOOKUP'!$C$4:$N$59,12,FALSE)),"0") -> 0 | DU7: =IF(AND($C7<>"",O7<>""),(VLOOKUP($C7,'V-LOOKUP'!$C$4:$M$59,4,FALSE)),"0") -> 0 | DV7: =IF(AND($C7<>"",$O7<>""),(VLOOKUP($C7,'V-LOOKUP'!$C$4:$M$59,5,FALSE)),"0") -> 0 | DW7: =IF(AND($C7<>"",$O7<>""),(VLOOKUP($C7,'V-LOOKUP'!$C$4:$M$59,6,FALSE)),"0") -> 0 | DX7: =IF(AND($C7<>"",$O7<>""),(VLOOKUP($C7,'V-LOOKUP'!$C$4:$M$59,7,FALSE)),"0") -> 0 | DY7: =IF(AND($C7<>"",$O7<>""),(VLOOKUP($C7,'V-LOOKUP'!$C$4:$M$59,8,FALSE)),"0") -> 0 | DZ7: =IF(AND($C7<>"",$O7<>""),(VLOOKUP($C7,'V-LOOKUP'!$C$4:$M$59,9,FALSE)),"0") -> 0 | EA7: =IF(AND($C7<>"",$O7<>""),(VLOOKUP($C7,'V-LOOKUP'!$C$4:$M$59,10,FALSE)),"0") -> 0 | EB7: =IF(AND($C7<>"",$O7<>""),(VLOOKUP($C7,'V-LOOKUP'!$C$4:$M$59,11,FALSE)),"0") -> 0 | EC7: =IF(AND($C7<>"",$O7<>""),(VLOOKUP($C7,'V-LOOKUP'!$C$4:$N$59,12,FALSE)),"0") -> 0 | ED7: =IF(AND($C7<>"",P7<>""),(VLOOKUP($C7,'V-LOOKUP'!$C$4:$M$59,4,FALSE)),"0") -> 0 | EE7: =IF(AND($C7<>"",$P7<>""),(VLOOKUP($C7,'V-LOOKUP'!$C$4:$M$59,5,FALSE)),"0") -> 0 | EF7: =IF(AND($C7<>"",$P7<>""),(VLOOKUP($C7,'V-LOOKUP'!$C$4:$M$59,6,FALSE)),"0") -> 0 | EG7: =IF(AND($C7<>"",$P7<>""),(VLOOKUP($C7,'V-LOOKUP'!$C$4:$M$59,7,FALSE)),"0") -> 0 | EH7: =IF(AND($C7<>"",$P7<>""),(VLOOKUP($C7,'V-LOOKUP'!$C$4:$M$59,8,FALSE)),"0") -> 0 | EI7: =IF(AND($C7<>"",$P7<>""),(VLOOKUP($C7,'V-LOOKUP'!$C$4:$M$59,9,FALSE)),"0") -> 0 | EJ7: =IF(AND($C7<>"",$P7<>""),(VLOOKUP($C7,'V-LOOKUP'!$C$4:$M$59,10,FALSE)),"0") -> 0 | EK7: =IF(AND($C7<>"",$P7<>""),(VLOOKUP($C7,'V-LOOKUP'!$C$4:$M$59,11,FALSE)),"0") -> 0 | EL7: =IF(AND($C7<>"",$P7<>""),(VLOOKUP($C7,'V-LOOKUP'!$C$4:$N$59,12,FALSE)),"0") -> 0 | EM7: =IF(AND($C7<>"",Q7<>""),(VLOOKUP($C7,'V-LOOKUP'!$C$4:$M$59,4,FALSE)),"0") -> 0 | EN7: =IF(AND($C7<>"",$Q7<>""),(VLOOKUP($C7,'V-LOOKUP'!$C$4:$M$59,5,FALSE)),"0") -> 0 | EO7: =IF(AND($C7<>"",$Q7<>""),(VLOOKUP($C7,'V-LOOKUP'!$C$4:$M$59,6,FALSE)),"0") -> 0 | EP7: =IF(AND($C7<>"",$Q7<>""),(VLOOKUP($C7,'V-LOOKUP'!$C$4:$M$59,7,FALSE)),"0") -> 0 | EQ7: =IF(AND($C7<>"",$Q7<>""),(VLOOKUP($C7,'V-LOOKUP'!$C$4:$M$59,8,FALSE)),"0") -> 0 | ER7: =IF(AND($C7<>"",$Q7<>""),(VLOOKUP($C7,'V-LOOKUP'!$C$4:$M$59,9,FALSE)),"0") -> 0 | ES7: =IF(AND($C7<>"",$Q7<>""),(VLOOKUP($C7,'V-LOOKUP'!$C$4:$M$59,10,FALSE)),"0") -> 0 | ET7: =IF(AND($C7<>"",$Q7<>""),(VLOOKUP($C7,'V-LOOKUP'!$C$4:$M$59,11,FALSE)),"0") -> 0 | EU7: =IF(AND($C7<>"",$Q7<>""),(VLOOKUP($C7,'V-LOOKUP'!$C$4:$N$59,12,FALSE)),"0") -> 0 | EV7: =IF(AND($C7<>"",R7<>""),(VLOOKUP($C7,'V-LOOKUP'!$C$4:$M$59,4,FALSE)),"0") -> 0 | EW7: =IF(AND($C7<>"",$R7<>""),(VLOOKUP($C7,'V-LOOKUP'!$C$4:$M$59,5,FALSE)),"0") -> 0 | EX7: =IF(AND($C7<>"",$R7<>""),(VLOOKUP($C7,'V-LOOKUP'!$C$4:$M$59,6,FALSE)),"0") -> 0 | EY7: =IF(AND($C7<>"",$R7<>""),(VLOOKUP($C7,'V-LOOKUP'!$C$4:$M$59,7,FALSE)),"0") -> 0 | EZ7: =IF(AND($C7<>"",$R7<>""),(VLOOKUP($C7,'V-LOOKUP'!$C$4:$M$59,8,FALSE)),"0") -> 0 | FA7: =IF(AND($C7<>"",$R7<>""),(VLOOKUP($C7,'V-LOOKUP'!$C$4:$M$59,9,FALSE)),"0") -> 0 | FB7: =IF(AND($C7<>"",$R7<>""),(VLOOKUP($C7,'V-LOOKUP'!$C$4:$M$59,10,FALSE)),"0") -> 0 | FC7: =IF(AND($C7<>"",$R7<>""),(VLOOKUP($C7,'V-LOOKUP'!$C$4:$M$59,11,FALSE)),"0") -> 0 | FD7: =IF(AND($C7<>"",$R7<>""),(VLOOKUP($C7,'V-LOOKUP'!$C$4:$N$59,12,FALSE)),"0") -> 0 | FE7: =IF(AND($C7<>"",S7<>""),(VLOOKUP($C7,'V-LOOKUP'!$C$4:$M$59,4,FALSE)),"0") -> 0 | FF7: =IF(AND($C7<>"",$S7<>""),(VLOOKUP($C7,'V-LOOKUP'!$C$4:$M$59,5,FALSE)),"0") -> 0 | FG7: =IF(AND($C7<>"",$S7<>""),(VLOOKUP($C7,'V-LOOKUP'!$C$4:$M$59,6,FALSE)),"0") -> 0 | FH7: =IF(AND($C7<>"",$S7<>""),(VLOOKUP($C7,'V-LOOKUP'!$C$4:$M$59,7,FALSE)),"0") -> 0 | FI7: =IF(AND($C7<>"",$S7<>""),(VLOOKUP($C7,'V-LOOKUP'!$C$4:$M$59,8,FALSE)),"0") -> 0 | FJ7: =IF(AND($C7<>"",$S7<>""),(VLOOKUP($C7,'V-LOOKUP'!$C$4:$M$59,9,FALSE)),"0") -> 0 | FK7: =IF(AND($C7<>"",$S7<>""),(VLOOKUP($C7,'V-LOOKUP'!$C$4:$M$59,10,FALSE)),"0") -> 0 | FL7: =IF(AND($C7<>"",$S7<>""),(VLOOKUP($C7,'V-LOOKUP'!$C$4:$M$59,11,FALSE)),"0") -> 0 | FM7: =IF(AND($C7<>"",$S7<>""),(VLOOKUP($C7,'V-LOOKUP'!$C$4:$N$59,12,FALSE)),"0") -> 0 | FN7: =IF(AND($C7<>"",T7<>""),(VLOOKUP($C7,'V-LOOKUP'!$C$4:$M$59,4,FALSE)),"0") -> 0 | FO7: =IF(AND($C7<>"",$T7<>""),(VLOOKUP($C7,'V-LOOKUP'!$C$4:$M$59,5,FALSE)),"0") -> 0 | FP7: =IF(AND($C7<>"",$T7<>""),(VLOOKUP($C7,'V-LOOKUP'!$C$4:$M$59,6,FALSE)),"0") -> 0 | FQ7: =IF(AND($C7<>"",$T7<>""),(VLOOKUP($C7,'V-LOOKUP'!$C$4:$M$59,7,FALSE)),"0") -> 0 | FR7: =IF(AND($C7<>"",$T7<>""),(VLOOKUP($C7,'V-LOOKUP'!$C$4:$M$59,8,FALSE)),"0") -> 0 | FS7: =IF(AND($C7<>"",$T7<>""),(VLOOKUP($C7,'V-LOOKUP'!$C$4:$M$59,9,FALSE)),"0") -> 0 | FT7: =IF(AND($C7<>"",$T7<>""),(VLOOKUP($C7,'V-LOOKUP'!$C$4:$M$59,10,FALSE)),"0") -> 0 | FU7: =IF(AND($C7<>"",$T7<>""),(VLOOKUP($C7,'V-LOOKUP'!$C$4:$M$59,11,FALSE)),"0") -> 0 | FV7: =IF(AND($C7<>"",$T7<>""),(VLOOKUP($C7,'V-LOOKUP'!$C$4:$N$59,12,FALSE)),"0") -> 0 | FW7: =IF(AND($C7<>"",U7<>""),(VLOOKUP($C7,'V-LOOKUP'!$C$4:$M$59,4,FALSE)),"0") -> 0 | FX7: =IF(AND($C7<>"",$U7<>""),(VLOOKUP($C7,'V-LOOKUP'!$C$4:$M$59,5,FALSE)),"0") -> 0 | FY7: =IF(AND($C7<>"",$U7<>""),(VLOOKUP($C7,'V-LOOKUP'!$C$4:$M$59,6,FALSE)),"0") -> 0 | FZ7: =IF(AND($C7<>"",$U7<>""),(VLOOKUP($C7,'V-LOOKUP'!$C$4:$M$59,7,FALSE)),"0") -> 0 | GA7: =IF(AND($C7<>"",$U7<>""),(VLOOKUP($C7,'V-LOOKUP'!$C$4:$M$59,8,FALSE)),"0") -> 0 | GB7: =IF(AND($C7<>"",$U7<>""),(VLOOKUP($C7,'V-LOOKUP'!$C$4:$M$59,9,FALSE)),"0") -> 0 | GC7: =IF(AND($C7<>"",$U7<>""),(VLOOKUP($C7,'V-LOOKUP'!$C$4:$M$59,10,FALSE)),"0") -> 0 | GD7: =IF(AND($C7<>"",$U7<>""),(VLOOKUP($C7,'V-LOOKUP'!$C$4:$M$59,11,FALSE)),"0") -> 0 | GE7: =IF(AND($C7<>"",$U7<>""),(VLOOKUP($C7,'V-LOOKUP'!$C$4:$N$59,12,FALSE)),"0") -> 0 | GF7: =IF(AND($C7<>"",V7<>""),(VLOOKUP($C7,'V-LOOKUP'!$C$4:$M$59,4,FALSE)),"0") -> 0 | GG7: =IF(AND($C7<>"",$V7<>""),(VLOOKUP($C7,'V-LOOKUP'!$C$4:$M$59,5,FALSE)),"0") -> 0 | GH7: =IF(AND($C7<>"",$V7<>""),(VLOOKUP($C7,'V-LOOKUP'!$C$4:$M$59,6,FALSE)),"0") -> 0 | GI7: =IF(AND($C7<>"",$V7<>""),(VLOOKUP($C7,'V-LOOKUP'!$C$4:$M$59,7,FALSE)),"0") -> 0 | GJ7: =IF(AND($C7<>"",$V7<>""),(VLOOKUP($C7,'V-LOOKUP'!$C$4:$M$59,8,FALSE)),"0") -> 0 | GK7: =IF(AND($C7<>"",$V7<>""),(VLOOKUP($C7,'V-LOOKUP'!$C$4:$M$59,9,FALSE)),"0") -> 0 | GL7: =IF(AND($C7<>"",$V7<>""),(VLOOKUP($C7,'V-LOOKUP'!$C$4:$M$59,10,FALSE)),"0") -> 0 | GM7: =IF(AND($C7<>"",$V7<>""),(VLOOKUP($C7,'V-LOOKUP'!$C$4:$M$59,11,FALSE)),"0") -> 0 | GN7: =IF(AND($C7<>"",$V7<>""),(VLOOKUP($C7,'V-LOOKUP'!$C$4:$N$59,12,FALSE)),"0") -> 0 | GO7: =IF(AND($C7<>"",W7<>""),(VLOOKUP($C7,'V-LOOKUP'!$C$4:$M$59,4,FALSE)),"0") -> 0 | GP7: =IF(AND($C7<>"",$W7<>""),(VLOOKUP($C7,'V-LOOKUP'!$C$4:$M$59,5,FALSE)),"0") -> 0 | GQ7: =IF(AND($C7<>"",$W7<>""),(VLOOKUP($C7,'V-LOOKUP'!$C$4:$M$59,6,FALSE)),"0") -> 0 | GR7: =IF(AND($C7<>"",$W7<>""),(VLOOKUP($C7,'V-LOOKUP'!$C$4:$M$59,7,FALSE)),"0") -> 0 | GS7: =IF(AND($C7<>"",$W7<>""),(VLOOKUP($C7,'V-LOOKUP'!$C$4:$M$59,8,FALSE)),"0") -> 0 | GT7: =IF(AND($C7<>"",$W7<>""),(VLOOKUP($C7,'V-LOOKUP'!$C$4:$M$59,9,FALSE)),"0") -> 0 | GU7: =IF(AND($C7<>"",$W7<>""),(VLOOKUP($C7,'V-LOOKUP'!$C$4:$M$59,10,FALSE)),"0") -> 0 | GV7: =IF(AND($C7<>"",$W7<>""),(VLOOKUP($C7,'V-LOOKUP'!$C$4:$M$59,11,FALSE)),"0") -> 0 | GW7: =IF(AND($C7<>"",$W7<>""),(VLOOKUP($C7,'V-LOOKUP'!$C$4:$N$59,12,FALSE)),"0") -> 0
Z8: =IF(AND($C8<>"",$D8<>""),(VLOOKUP($C8,'V-LOOKUP'!$C$4:$M$59,4,FALSE)),"0") -> 0 | AA8: =IF(AND($C8<>"",$D8<>""),(VLOOKUP($C8,'V-LOOKUP'!$C$4:$M$59,5,FALSE)),"0") -> 0 | AB8: =IF(AND($C8<>"",$D8<>""),(VLOOKUP($C8,'V-LOOKUP'!$C$4:$M$59,6,FALSE)),"0") -> 0 | AC8: =IF(AND($C8<>"",$D8<>""),(VLOOKUP($C8,'V-LOOKUP'!$C$4:$M$59,7,FALSE)),"0") -> 0 | AD8: =IF(AND($C8<>"",$D8<>""),(VLOOKUP($C8,'V-LOOKUP'!$C$4:$M$59,8,FALSE)),"0") -> 0 | AE8: =IF(AND($C8<>"",$D8<>""),(VLOOKUP($C8,'V-LOOKUP'!$C$4:$M$59,9,FALSE)),"0") -> 0 | AF8: =IF(AND($C8<>"",$D8<>""),(VLOOKUP($C8,'V-LOOKUP'!$C$4:$M$59,10,FALSE)),"0") -> 0 | AG8: =IF(AND($C8<>"",$D8<>""),(VLOOKUP($C8,'V-LOOKUP'!$C$4:$M$59,11,FALSE)),"0") -> 0 | AH8: =IF(AND($C8<>"",$D8<>""),(VLOOKUP($C8,'V-LOOKUP'!$C$4:$N$59,12,FALSE)),"0") -> 0 | AI8: =IF(AND($C8<>"",E8<>""),(VLOOKUP($C8,'V-LOOKUP'!$C$4:$M$59,4,FALSE)),"0") -> 0 | AJ8: =IF(AND($C8<>"",$E8<>""),(VLOOKUP($C8,'V-LOOKUP'!$C$4:$M$59,5,FALSE)),"0") -> 0 | AK8: =IF(AND($C8<>"",$E8<>""),(VLOOKUP($C8,'V-LOOKUP'!$C$4:$M$59,6,FALSE)),"0") -> 0 | AL8: =IF(AND($C8<>"",$E8<>""),(VLOOKUP($C8,'V-LOOKUP'!$C$4:$M$59,7,FALSE)),"0") -> 0 | AM8: =IF(AND($C8<>"",$E8<>""),(VLOOKUP($C8,'V-LOOKUP'!$C$4:$M$59,8,FALSE)),"0") -> 0 | AN8: =IF(AND($C8<>"",$E8<>""),(VLOOKUP($C8,'V-LOOKUP'!$C$4:$M$59,9,FALSE)),"0") -> 0 | AO8: =IF(AND($C8<>"",$E8<>""),(VLOOKUP($C8,'V-LOOKUP'!$C$4:$M$59,10,FALSE)),"0") -> 0 | AP8: =IF(AND($C8<>"",$E8<>""),(VLOOKUP($C8,'V-LOOKUP'!$C$4:$M$59,11,FALSE)),"0") -> 0 | AQ8: =IF(AND($C8<>"",$E8<>""),(VLOOKUP($C8,'V-LOOKUP'!$C$4:$N$59,12,FALSE)),"0") -> 0 | AR8: =IF(AND($C8<>"",$F8<>""),(VLOOKUP($C8,'V-LOOKUP'!$C$4:$M$59,4,FALSE)),"0") -> 0 | AS8: =IF(AND($C8<>"",$F8<>""),(VLOOKUP($C8,'V-LOOKUP'!$C$4:$M$59,5,FALSE)),"0") -> 0 | AT8: =IF(AND($C8<>"",$F8<>""),(VLOOKUP($C8,'V-LOOKUP'!$C$4:$M$59,6,FALSE)),"0") -> 0 | AU8: =IF(AND($C8<>"",$F8<>""),(VLOOKUP($C8,'V-LOOKUP'!$C$4:$M$59,7,FALSE)),"0") -> 0 | AV8: =IF(AND($C8<>"",$F8<>""),(VLOOKUP($C8,'V-LOOKUP'!$C$4:$M$59,8,FALSE)),"0") -> 0 | AW8: =IF(AND($C8<>"",$F8<>""),(VLOOKUP($C8,'V-LOOKUP'!$C$4:$M$59,9,FALSE)),"0") -> 0 | AX8: =IF(AND($C8<>"",$F8<>""),(VLOOKUP($C8,'V-LOOKUP'!$C$4:$M$59,10,FALSE)),"0") -> 0 | AY8: =IF(AND($C8<>"",$F8<>""),(VLOOKUP($C8,'V-LOOKUP'!$C$4:$M$59,11,FALSE)),"0") -> 0 | AZ8: =IF(AND($C8<>"",$F8<>""),(VLOOKUP($C8,'V-LOOKUP'!$C$4:$N$59,12,FALSE)),"0") -> 0 | BA8: =IF(AND($C8<>"",G8<>""),(VLOOKUP($C8,'V-LOOKUP'!$C$4:$M$59,4,FALSE)),"0") -> 0 | BB8: =IF(AND($C8<>"",$G8<>""),(VLOOKUP($C8,'V-LOOKUP'!$C$4:$M$59,5,FALSE)),"0") -> 0 | BC8: =IF(AND($C8<>"",$G8<>""),(VLOOKUP($C8,'V-LOOKUP'!$C$4:$M$59,6,FALSE)),"0") -> 0 | BD8: =IF(AND($C8<>"",$G8<>""),(VLOOKUP($C8,'V-LOOKUP'!$C$4:$M$59,7,FALSE)),"0") -> 0 | BE8: =IF(AND($C8<>"",$G8<>""),(VLOOKUP($C8,'V-LOOKUP'!$C$4:$M$59,8,FALSE)),"0") -> 0 | BF8: =IF(AND($C8<>"",$G8<>""),(VLOOKUP($C8,'V-LOOKUP'!$C$4:$M$59,9,FALSE)),"0") -> 0 | BG8: =IF(AND($C8<>"",$G8<>""),(VLOOKUP($C8,'V-LOOKUP'!$C$4:$M$59,10,FALSE)),"0") -> 0 | BH8: =IF(AND($C8<>"",$G8<>""),(VLOOKUP($C8,'V-LOOKUP'!$C$4:$M$59,11,FALSE)),"0") -> 0 | BI8: =IF(AND($C8<>"",$G8<>""),(VLOOKUP($C8,'V-LOOKUP'!$C$4:$N$59,12,FALSE)),"0") -> 0 | BJ8: =IF(AND($C8<>"",H8<>""),(VLOOKUP($C8,'V-LOOKUP'!$C$4:$M$59,4,FALSE)),"0") -> 0 | BK8: =IF(AND($C8<>"",$G8<>""),(VLOOKUP($C8,'V-LOOKUP'!$C$4:$M$59,5,FALSE)),"0") -> 0 | BL8: =IF(AND($C8<>"",$H8<>""),(VLOOKUP($C8,'V-LOOKUP'!$C$4:$M$59,6,FALSE)),"0") -> 0 | BM8: =IF(AND($C8<>"",$H8<>""),(VLOOKUP($C8,'V-LOOKUP'!$C$4:$M$59,7,FALSE)),"0") -> 0 | BN8: =IF(AND($C8<>"",$H8<>""),(VLOOKUP($C8,'V-LOOKUP'!$C$4:$M$59,8,FALSE)),"0") -> 0 | BO8: =IF(AND($C8<>"",$H8<>""),(VLOOKUP($C8,'V-LOOKUP'!$C$4:$M$59,9,FALSE)),"0") -> 0 | BP8: =IF(AND($C8<>"",$H8<>""),(VLOOKUP($C8,'V-LOOKUP'!$C$4:$M$59,10,FALSE)),"0") -> 0 | BQ8: =IF(AND($C8<>"",$H8<>""),(VLOOKUP($C8,'V-LOOKUP'!$C$4:$M$59,11,FALSE)),"0") -> 0 | BR8: =IF(AND($C8<>"",$H8<>""),(VLOOKUP($C8,'V-LOOKUP'!$C$4:$N$59,12,FALSE)),"0") -> 0 | BS8: =IF(AND($C8<>"",I8<>""),(VLOOKUP($C8,'V-LOOKUP'!$C$4:$M$59,4,FALSE)),"0") -> 0 | BT8: =IF(AND($C8<>"",$I8<>""),(VLOOKUP($C8,'V-LOOKUP'!$C$4:$M$59,5,FALSE)),"0") -> 0 | BU8: =IF(AND($C8<>"",$I8<>""),(VLOOKUP($C8,'V-LOOKUP'!$C$4:$M$59,6,FALSE)),"0") -> 0 | BV8: =IF(AND($C8<>"",$I8<>""),(VLOOKUP($C8,'V-LOOKUP'!$C$4:$M$59,7,FALSE)),"0") -> 0 | BW8: =IF(AND($C8<>"",$I8<>""),(VLOOKUP($C8,'V-LOOKUP'!$C$4:$M$59,8,FALSE)),"0") -> 0 | BX8: =IF(AND($C8<>"",$I8<>""),(VLOOKUP($C8,'V-LOOKUP'!$C$4:$M$59,9,FALSE)),"0") -> 0 | BY8: =IF(AND($C8<>"",$I8<>""),(VLOOKUP($C8,'V-LOOKUP'!$C$4:$M$59,10,FALSE)),"0") -> 0 | BZ8: =IF(AND($C8<>"",$I8<>""),(VLOOKUP($C8,'V-LOOKUP'!$C$4:$M$59,11,FALSE)),"0") -> 0 | CA8: =IF(AND($C8<>"",$I8<>""),(VLOOKUP($C8,'V-LOOKUP'!$C$4:$N$59,12,FALSE)),"0") -> 0 | CB8: =IF(AND($C8<>"",J8<>""),(VLOOKUP($C8,'V-LOOKUP'!$C$4:$M$59,4,FALSE)),"0") -> 0 | CC8: =IF(AND($C8<>"",$J8<>""),(VLOOKUP($C8,'V-LOOKUP'!$C$4:$M$59,5,FALSE)),"0") -> 0 | CD8: =IF(AND($C8<>"",$J8<>""),(VLOOKUP($C8,'V-LOOKUP'!$C$4:$M$59,6,FALSE)),"0") -> 0 | CE8: =IF(AND($C8<>"",$J8<>""),(VLOOKUP($C8,'V-LOOKUP'!$C$4:$M$59,7,FALSE)),"0") -> 0 | CF8: =IF(AND($C8<>"",$J8<>""),(VLOOKUP($C8,'V-LOOKUP'!$C$4:$M$59,8,FALSE)),"0") -> 0 | CG8: =IF(AND($C8<>"",$J8<>""),(VLOOKUP($C8,'V-LOOKUP'!$C$4:$M$59,9,FALSE)),"0") -> 0 | CH8: =IF(AND($C8<>"",$J8<>""),(VLOOKUP($C8,'V-LOOKUP'!$C$4:$M$59,10,FALSE)),"0") -> 0 | CI8: =IF(AND($C8<>"",$J8<>""),(VLOOKUP($C8,'V-LOOKUP'!$C$4:$M$59,11,FALSE)),"0") -> 0 | CJ8: =IF(AND($C8<>"",$J8<>""),(VLOOKUP($C8,'V-LOOKUP'!$C$4:$N$59,12,FALSE)),"0") -> 0 | CK8: =IF(AND($C8<>"",K8<>""),(VLOOKUP($C8,'V-LOOKUP'!$C$4:$M$59,4,FALSE)),"0") -> 0 | CL8: =IF(AND($C8<>"",$K8<>""),(VLOOKUP($C8,'V-LOOKUP'!$C$4:$M$59,5,FALSE)),"0") -> 0 | CM8: =IF(AND($C8<>"",$K8<>""),(VLOOKUP($C8,'V-LOOKUP'!$C$4:$M$59,6,FALSE)),"0") -> 0 | CN8: =IF(AND($C8<>"",$K8<>""),(VLOOKUP($C8,'V-LOOKUP'!$C$4:$M$59,7,FALSE)),"0") -> 0 | CO8: =IF(AND($C8<>"",$K8<>""),(VLOOKUP($C8,'V-LOOKUP'!$C$4:$M$59,8,FALSE)),"0") -> 0 | CP8: =IF(AND($C8<>"",$K8<>""),(VLOOKUP($C8,'V-LOOKUP'!$C$4:$M$59,9,FALSE)),"0") -> 0 | CQ8: =IF(AND($C8<>"",$K8<>""),(VLOOKUP($C8,'V-LOOKUP'!$C$4:$M$59,10,FALSE)),"0") -> 0 | CR8: =IF(AND($C8<>"",$K8<>""),(VLOOKUP($C8,'V-LOOKUP'!$C$4:$M$59,11,FALSE)),"0") -> 0 | CS8: =IF(AND($C8<>"",$K8<>""),(VLOOKUP($C8,'V-LOOKUP'!$C$4:$N$59,12,FALSE)),"0") -> 0 | CT8: =IF(AND($C8<>"",L8<>""),(VLOOKUP($C8,'V-LOOKUP'!$C$4:$M$59,4,FALSE)),"0") -> 0 | CU8: =IF(AND($C8<>"",$L8<>""),(VLOOKUP($C8,'V-LOOKUP'!$C$4:$M$59,5,FALSE)),"0") -> 0 | CV8: =IF(AND($C8<>"",$L8<>""),(VLOOKUP($C8,'V-LOOKUP'!$C$4:$M$59,6,FALSE)),"0") -> 0 | CW8: =IF(AND($C8<>"",$L8<>""),(VLOOKUP($C8,'V-LOOKUP'!$C$4:$M$59,7,FALSE)),"0") -> 0 | CX8: =IF(AND($C8<>"",$L8<>""),(VLOOKUP($C8,'V-LOOKUP'!$C$4:$M$59,8,FALSE)),"0") -> 0 | CY8: =IF(AND($C8<>"",$L8<>""),(VLOOKUP($C8,'V-LOOKUP'!$C$4:$M$59,9,FALSE)),"0") -> 0 | CZ8: =IF(AND($C8<>"",$L8<>""),(VLOOKUP($C8,'V-LOOKUP'!$C$4:$M$59,10,FALSE)),"0") -> 0 | DA8: =IF(AND($C8<>"",$L8<>""),(VLOOKUP($C8,'V-LOOKUP'!$C$4:$M$59,11,FALSE)),"0") -> 0 | DB8: =IF(AND($C8<>"",$L8<>""),(VLOOKUP($C8,'V-LOOKUP'!$C$4:$N$59,12,FALSE)),"0") -> 0 | DC8: =IF(AND($C8<>"",M8<>""),(VLOOKUP($C8,'V-LOOKUP'!$C$4:$M$59,4,FALSE)),"0") -> 0 | DD8: =IF(AND($C8<>"",$M8<>""),(VLOOKUP($C8,'V-LOOKUP'!$C$4:$M$59,5,FALSE)),"0") -> 0 | DE8: =IF(AND($C8<>"",$M8<>""),(VLOOKUP($C8,'V-LOOKUP'!$C$4:$M$59,6,FALSE)),"0") -> 0 | DF8: =IF(AND($C8<>"",$M8<>""),(VLOOKUP($C8,'V-LOOKUP'!$C$4:$M$59,7,FALSE)),"0") -> 0 | DG8: =IF(AND($C8<>"",$M8<>""),(VLOOKUP($C8,'V-LOOKUP'!$C$4:$M$59,8,FALSE)),"0") -> 0 | DH8: =IF(AND($C8<>"",$M8<>""),(VLOOKUP($C8,'V-LOOKUP'!$C$4:$M$59,9,FALSE)),"0") -> 0 | DI8: =IF(AND($C8<>"",$M8<>""),(VLOOKUP($C8,'V-LOOKUP'!$C$4:$M$59,10,FALSE)),"0") -> 0 | DJ8: =IF(AND($C8<>"",$M8<>""),(VLOOKUP($C8,'V-LOOKUP'!$C$4:$M$59,11,FALSE)),"0") -> 0 | DK8: =IF(AND($C8<>"",$M8<>""),(VLOOKUP($C8,'V-LOOKUP'!$C$4:$N$59,12,FALSE)),"0") -> 0 | DL8: =IF(AND($C8<>"",$N8<>""),(VLOOKUP($C8,'V-LOOKUP'!$C$4:$M$59,4,FALSE)),"0") -> 0 | DM8: =IF(AND($C8<>"",$N8<>""),(VLOOKUP($C8,'V-LOOKUP'!$C$4:$M$59,5,FALSE)),"0") -> 0 | DN8: =IF(AND($C8<>"",$N8<>""),(VLOOKUP($C8,'V-LOOKUP'!$C$4:$M$59,6,FALSE)),"0") -> 0 | DO8: =IF(AND($C8<>"",$N8<>""),(VLOOKUP($C8,'V-LOOKUP'!$C$4:$M$59,7,FALSE)),"0") -> 0 | DP8: =IF(AND($C8<>"",$N8<>""),(VLOOKUP($C8,'V-LOOKUP'!$C$4:$M$59,8,FALSE)),"0") -> 0 | DQ8: =IF(AND($C8<>"",$N8<>""),(VLOOKUP($C8,'V-LOOKUP'!$C$4:$M$59,9,FALSE)),"0") -> 0 | DR8: =IF(AND($C8<>"",$N8<>""),(VLOOKUP($C8,'V-LOOKUP'!$C$4:$M$59,10,FALSE)),"0") -> 0 | DS8: =IF(AND($C8<>"",$N8<>""),(VLOOKUP($C8,'V-LOOKUP'!$C$4:$M$59,11,FALSE)),"0") -> 0 | DT8: =IF(AND($C8<>"",$N8<>""),(VLOOKUP($C8,'V-LOOKUP'!$C$4:$N$59,12,FALSE)),"0") -> 0 | DU8: =IF(AND($C8<>"",O8<>""),(VLOOKUP($C8,'V-LOOKUP'!$C$4:$M$59,4,FALSE)),"0") -> 0 | DV8: =IF(AND($C8<>"",$O8<>""),(VLOOKUP($C8,'V-LOOKUP'!$C$4:$M$59,5,FALSE)),"0") -> 0 | DW8: =IF(AND($C8<>"",$O8<>""),(VLOOKUP($C8,'V-LOOKUP'!$C$4:$M$59,6,FALSE)),"0") -> 0 | DX8: =IF(AND($C8<>"",$O8<>""),(VLOOKUP($C8,'V-LOOKUP'!$C$4:$M$59,7,FALSE)),"0") -> 0 | DY8: =IF(AND($C8<>"",$O8<>""),(VLOOKUP($C8,'V-LOOKUP'!$C$4:$M$59,8,FALSE)),"0") -> 0 | DZ8: =IF(AND($C8<>"",$O8<>""),(VLOOKUP($C8,'V-LOOKUP'!$C$4:$M$59,9,FALSE)),"0") -> 0 | EA8: =IF(AND($C8<>"",$O8<>""),(VLOOKUP($C8,'V-LOOKUP'!$C$4:$M$59,10,FALSE)),"0") -> 0 | EB8: =IF(AND($C8<>"",$O8<>""),(VLOOKUP($C8,'V-LOOKUP'!$C$4:$M$59,11,FALSE)),"0") -> 0 | EC8: =IF(AND($C8<>"",$O8<>""),(VLOOKUP($C8,'V-LOOKUP'!$C$4:$N$59,12,FALSE)),"0") -> 0 | ED8: =IF(AND($C8<>"",P8<>""),(VLOOKUP($C8,'V-LOOKUP'!$C$4:$M$59,4,FALSE)),"0") -> 0 | EE8: =IF(AND($C8<>"",$P8<>""),(VLOOKUP($C8,'V-LOOKUP'!$C$4:$M$59,5,FALSE)),"0") -> 0 | EF8: =IF(AND($C8<>"",$P8<>""),(VLOOKUP($C8,'V-LOOKUP'!$C$4:$M$59,6,FALSE)),"0") -> 0 | EG8: =IF(AND($C8<>"",$P8<>""),(VLOOKUP($C8,'V-LOOKUP'!$C$4:$M$59,7,FALSE)),"0") -> 0 | EH8: =IF(AND($C8<>"",$P8<>""),(VLOOKUP($C8,'V-LOOKUP'!$C$4:$M$59,8,FALSE)),"0") -> 0 | EI8: =IF(AND($C8<>"",$P8<>""),(VLOOKUP($C8,'V-LOOKUP'!$C$4:$M$59,9,FALSE)),"0") -> 0 | EJ8: =IF(AND($C8<>"",$P8<>""),(VLOOKUP($C8,'V-LOOKUP'!$C$4:$M$59,10,FALSE)),"0") -> 0 | EK8: =IF(AND($C8<>"",$P8<>""),(VLOOKUP($C8,'V-LOOKUP'!$C$4:$M$59,11,FALSE)),"0") -> 0 | EL8: =IF(AND($C8<>"",$P8<>""),(VLOOKUP($C8,'V-LOOKUP'!$C$4:$N$59,12,FALSE)),"0") -> 0 | EM8: =IF(AND($C8<>"",Q8<>""),(VLOOKUP($C8,'V-LOOKUP'!$C$4:$M$59,4,FALSE)),"0") -> 0 | EN8: =IF(AND($C8<>"",$Q8<>""),(VLOOKUP($C8,'V-LOOKUP'!$C$4:$M$59,5,FALSE)),"0") -> 0 | EO8: =IF(AND($C8<>"",$Q8<>""),(VLOOKUP($C8,'V-LOOKUP'!$C$4:$M$59,6,FALSE)),"0") -> 0 | EP8: =IF(AND($C8<>"",$Q8<>""),(VLOOKUP($C8,'V-LOOKUP'!$C$4:$M$59,7,FALSE)),"0") -> 0 | EQ8: =IF(AND($C8<>"",$Q8<>""),(VLOOKUP($C8,'V-LOOKUP'!$C$4:$M$59,8,FALSE)),"0") -> 0 | ER8: =IF(AND($C8<>"",$Q8<>""),(VLOOKUP($C8,'V-LOOKUP'!$C$4:$M$59,9,FALSE)),"0") -> 0 | ES8: =IF(AND($C8<>"",$Q8<>""),(VLOOKUP($C8,'V-LOOKUP'!$C$4:$M$59,10,FALSE)),"0") -> 0 | ET8: =IF(AND($C8<>"",$Q8<>""),(VLOOKUP($C8,'V-LOOKUP'!$C$4:$M$59,11,FALSE)),"0") -> 0 | EU8: =IF(AND($C8<>"",$Q8<>""),(VLOOKUP($C8,'V-LOOKUP'!$C$4:$N$59,12,FALSE)),"0") -> 0 | EV8: =IF(AND($C8<>"",R8<>""),(VLOOKUP($C8,'V-LOOKUP'!$C$4:$M$59,4,FALSE)),"0") -> 0 | EW8: =IF(AND($C8<>"",$R8<>""),(VLOOKUP($C8,'V-LOOKUP'!$C$4:$M$59,5,FALSE)),"0") -> 0 | EX8: =IF(AND($C8<>"",$R8<>""),(VLOOKUP($C8,'V-LOOKUP'!$C$4:$M$59,6,FALSE)),"0") -> 0 | EY8: =IF(AND($C8<>"",$R8<>""),(VLOOKUP($C8,'V-LOOKUP'!$C$4:$M$59,7,FALSE)),"0") -> 0 | EZ8: =IF(AND($C8<>"",$R8<>""),(VLOOKUP($C8,'V-LOOKUP'!$C$4:$M$59,8,FALSE)),"0") -> 0 | FA8: =IF(AND($C8<>"",$R8<>""),(VLOOKUP($C8,'V-LOOKUP'!$C$4:$M$59,9,FALSE)),"0") -> 0 | FB8: =IF(AND($C8<>"",$R8<>""),(VLOOKUP($C8,'V-LOOKUP'!$C$4:$M$59,10,FALSE)),"0") -> 0 | FC8: =IF(AND($C8<>"",$R8<>""),(VLOOKUP($C8,'V-LOOKUP'!$C$4:$M$59,11,FALSE)),"0") -> 0 | FD8: =IF(AND($C8<>"",$R8<>""),(VLOOKUP($C8,'V-LOOKUP'!$C$4:$N$59,12,FALSE)),"0") -> 0 | FE8: =IF(AND($C8<>"",S8<>""),(VLOOKUP($C8,'V-LOOKUP'!$C$4:$M$59,4,FALSE)),"0") -> 0 | FF8: =IF(AND($C8<>"",$S8<>""),(VLOOKUP($C8,'V-LOOKUP'!$C$4:$M$59,5,FALSE)),"0") -> 0 | FG8: =IF(AND($C8<>"",$S8<>""),(VLOOKUP($C8,'V-LOOKUP'!$C$4:$M$59,6,FALSE)),"0") -> 0 | FH8: =IF(AND($C8<>"",$S8<>""),(VLOOKUP($C8,'V-LOOKUP'!$C$4:$M$59,7,FALSE)),"0") -> 0 | FI8: =IF(AND($C8<>"",$S8<>""),(VLOOKUP($C8,'V-LOOKUP'!$C$4:$M$59,8,FALSE)),"0") -> 0 | FJ8: =IF(AND($C8<>"",$S8<>""),(VLOOKUP($C8,'V-LOOKUP'!$C$4:$M$59,9,FALSE)),"0") -> 0 | FK8: =IF(AND($C8<>"",$S8<>""),(VLOOKUP($C8,'V-LOOKUP'!$C$4:$M$59,10,FALSE)),"0") -> 0 | FL8: =IF(AND($C8<>"",$S8<>""),(VLOOKUP($C8,'V-LOOKUP'!$C$4:$M$59,11,FALSE)),"0") -> 0 | FM8: =IF(AND($C8<>"",$S8<>""),(VLOOKUP($C8,'V-LOOKUP'!$C$4:$N$59,12,FALSE)),"0") -> 0 | FN8: =IF(AND($C8<>"",T8<>""),(VLOOKUP($C8,'V-LOOKUP'!$C$4:$M$59,4,FALSE)),"0") -> 0 | FO8: =IF(AND($C8<>"",$T8<>""),(VLOOKUP($C8,'V-LOOKUP'!$C$4:$M$59,5,FALSE)),"0") -> 0 | FP8: =IF(AND($C8<>"",$T8<>""),(VLOOKUP($C8,'V-LOOKUP'!$C$4:$M$59,6,FALSE)),"0") -> 0 | FQ8: =IF(AND($C8<>"",$T8<>""),(VLOOKUP($C8,'V-LOOKUP'!$C$4:$M$59,7,FALSE)),"0") -> 0 | FR8: =IF(AND($C8<>"",$T8<>""),(VLOOKUP($C8,'V-LOOKUP'!$C$4:$M$59,8,FALSE)),"0") -> 0 | FS8: =IF(AND($C8<>"",$T8<>""),(VLOOKUP($C8,'V-LOOKUP'!$C$4:$M$59,9,FALSE)),"0") -> 0 | FT8: =IF(AND($C8<>"",$T8<>""),(VLOOKUP($C8,'V-LOOKUP'!$C$4:$M$59,10,FALSE)),"0") -> 0 | FU8: =IF(AND($C8<>"",$T8<>""),(VLOOKUP($C8,'V-LOOKUP'!$C$4:$M$59,11,FALSE)),"0") -> 0 | FV8: =IF(AND($C8<>"",$T8<>""),(VLOOKUP($C8,'V-LOOKUP'!$C$4:$N$59,12,FALSE)),"0") -> 0 | FW8: =IF(AND($C8<>"",U8<>""),(VLOOKUP($C8,'V-LOOKUP'!$C$4:$M$59,4,FALSE)),"0") -> 0 | FX8: =IF(AND($C8<>"",$U8<>""),(VLOOKUP($C8,'V-LOOKUP'!$C$4:$M$59,5,FALSE)),"0") -> 0 | FY8: =IF(AND($C8<>"",$U8<>""),(VLOOKUP($C8,'V-LOOKUP'!$C$4:$M$59,6,FALSE)),"0") -> 0 | FZ8: =IF(AND($C8<>"",$U8<>""),(VLOOKUP($C8,'V-LOOKUP'!$C$4:$M$59,7,FALSE)),"0") -> 0 | GA8: =IF(AND($C8<>"",$U8<>""),(VLOOKUP($C8,'V-LOOKUP'!$C$4:$M$59,8,FALSE)),"0") -> 0 | GB8: =IF(AND($C8<>"",$U8<>""),(VLOOKUP($C8,'V-LOOKUP'!$C$4:$M$59,9,FALSE)),"0") -> 0 | GC8: =IF(AND($C8<>"",$U8<>""),(VLOOKUP($C8,'V-LOOKUP'!$C$4:$M$59,10,FALSE)),"0") -> 0 | GD8: =IF(AND($C8<>"",$U8<>""),(VLOOKUP($C8,'V-LOOKUP'!$C$4:$M$59,11,FALSE)),"0") -> 0 | GE8: =IF(AND($C8<>"",$U8<>""),(VLOOKUP($C8,'V-LOOKUP'!$C$4:$N$59,12,FALSE)),"0") -> 0 | GF8: =IF(AND($C8<>"",V8<>""),(VLOOKUP($C8,'V-LOOKUP'!$C$4:$M$59,4,FALSE)),"0") -> 0 | GG8: =IF(AND($C8<>"",$V8<>""),(VLOOKUP($C8,'V-LOOKUP'!$C$4:$M$59,5,FALSE)),"0") -> 0 | GH8: =IF(AND($C8<>"",$V8<>""),(VLOOKUP($C8,'V-LOOKUP'!$C$4:$M$59,6,FALSE)),"0") -> 0 | GI8: =IF(AND($C8<>"",$V8<>""),(VLOOKUP($C8,'V-LOOKUP'!$C$4:$M$59,7,FALSE)),"0") -> 0 | GJ8: =IF(AND($C8<>"",$V8<>""),(VLOOKUP($C8,'V-LOOKUP'!$C$4:$M$59,8,FALSE)),"0") -> 0 | GK8: =IF(AND($C8<>"",$V8<>""),(VLOOKUP($C8,'V-LOOKUP'!$C$4:$M$59,9,FALSE)),"0") -> 0 | GL8: =IF(AND($C8<>"",$V8<>""),(VLOOKUP($C8,'V-LOOKUP'!$C$4:$M$59,10,FALSE)),"0") -> 0 | GM8: =IF(AND($C8<>"",$V8<>""),(VLOOKUP($C8,'V-LOOKUP'!$C$4:$M$59,11,FALSE)),"0") -> 0 | GN8: =IF(AND($C8<>"",$V8<>""),(VLOOKUP($C8,'V-LOOKUP'!$C$4:$N$59,12,FALSE)),"0") -> 0 | GO8: =IF(AND($C8<>"",W8<>""),(VLOOKUP($C8,'V-LOOKUP'!$C$4:$M$59,4,FALSE)),"0") -> 0 | GP8: =IF(AND($C8<>"",$W8<>""),(VLOOKUP($C8,'V-LOOKUP'!$C$4:$M$59,5,FALSE)),"0") -> 0 | GQ8: =IF(AND($C8<>"",$W8<>""),(VLOOKUP($C8,'V-LOOKUP'!$C$4:$M$59,6,FALSE)),"0") -> 0 | GR8: =IF(AND($C8<>"",$W8<>""),(VLOOKUP($C8,'V-LOOKUP'!$C$4:$M$59,7,FALSE)),"0") -> 0 | GS8: =IF(AND($C8<>"",$W8<>""),(VLOOKUP($C8,'V-LOOKUP'!$C$4:$M$59,8,FALSE)),"0") -> 0 | GT8: =IF(AND($C8<>"",$W8<>""),(VLOOKUP($C8,'V-LOOKUP'!$C$4:$M$59,9,FALSE)),"0") -> 0 | GU8: =IF(AND($C8<>"",$W8<>""),(VLOOKUP($C8,'V-LOOKUP'!$C$4:$M$59,10,FALSE)),"0") -> 0 | GV8: =IF(AND($C8<>"",$W8<>""),(VLOOKUP($C8,'V-LOOKUP'!$C$4:$M$59,11,FALSE)),"0") -> 0 | GW8: =IF(AND($C8<>"",$W8<>""),(VLOOKUP($C8,'V-LOOKUP'!$C$4:$N$59,12,FALSE)),"0") -> 0
